<mujoco model="CMU Mk 5">
  <compiler angle="radian" meshdir="meshes/" autolimits="true"/>
  
  <option timestep="0.005" gravity="0 0 0"/>

  <default/>

  <asset>
  <texture type="skybox" builtin="gradient" rgb1=".3 .5 .7" rgb2="0 0 0" width="32" height="512"/>
    <texture name="body" type="cube" builtin="flat" mark="cross" width="127" height="1278" rgb1="0.8 0.6 0.4" rgb2="0.8 0.6 0.4" markrgb="1 1 1" random="0.01"/>
    <material name="body" texture="body" texuniform="true" rgba="0.8 0.6 .4 1"/>
    <texture name="grid" type="2d" builtin="checker" width="512" height="512" rgb1=".1 .2 .3" rgb2=".2 .3 .4"/>
    <material name="grid" texture="grid" texrepeat="1 1" texuniform="true" reflectance=".2"/>
    
    <mesh name="base_link" file="base_link.STL"/>
    <mesh name="base_link_collision" file="base_link_collision.STL"/>
    <mesh name="R_Hip_1" file="R_Hip_1.STL"/>
    <mesh name="R_Hip_2" file="R_Hip_2.STL"/>
    <mesh name="R_Thigh" file="R_Thigh.STL"/>
    <mesh name="R_Foreleg" file="R_Foreleg.STL"/>
    <mesh name="R_Shin" file="R_Shin.STL"/>
    <mesh name="R_Foot" file="R_Foot.STL"/>
    <mesh name="R_Foot_collision" file="R_Foot_collision.STL"/>
    <mesh name="R_Servo" file="R_Servo.STL"/>
    <mesh name="R_Servo_collision" file="R_Servo_collision.STL"/>
    <mesh name="R_Servo_Link" file="R_Servo_Link.STL"/>
    <mesh name="R_Linkage" file="R_Linkage.STL"/>
    <mesh name="L_Hip_1" file="L_Hip_1.STL"/>
    <mesh name="L_Hip_2" file="L_Hip_2.STL"/>
    <mesh name="L_Thigh" file="L_Thigh.STL"/>
    <mesh name="L_Foreleg" file="L_Foreleg.STL"/>
    <mesh name="L_Shin" file="L_Shin.STL"/>
    <mesh name="L_Foot" file="L_Foot.STL"/>
    <mesh name="L_Foot_collision" file="L_Foot_collision.STL"/>
    <mesh name="L_Servo" file="L_Servo.STL"/>
    <mesh name="L_Servo_collision" file="L_Servo_collision.STL"/>
    <mesh name="L_Servo_Link" file="L_Servo_Link.STL"/>
    <mesh name="L_Linkage" file="L_Linkage.STL"/>
  </asset>
  
  <worldbody>
    <geom name="floor" pos="0 0 0" size="0 0 .05" type="plane" material="grid" condim="3"/>
    
    <light name="spotlight" mode="targetbodycom" target="base link" pos="0 6 4" castshadow="false"/>
    
    <body name="base link" pos="0 0 .2">    
      <camera name="track" pos="0 -3 1" zaxis="0 -1 0.5" mode="track"/>
      <inertial pos="0 0 0" mass="0.0299227589680342" fullinertia="4.64430780114595E-06 4.78982197003375E-06 5.96248441172554E-06 -7.0005651433527E-12 1.45948993644989E-11 -7.65792898200085E-08"/>
      
      <!--freejoint/-->

      <geom type="mesh" contype="0" conaffinity="0" group="1" density="0" rgba="0.501961 0.501961 0.501961 1" mesh="base_link"/>
      <geom type="mesh" rgba="0.501961 0.501961 0.501961 1" mesh="base_link_collision"/>      
      
      <body name="R_Hip_1" pos="0.021005 0 0" quat="0.706765 0.706768 -0.0219327 0.0219327">
        <inertial pos="-3.00471e-07 -4.83658e-06 0.00581975" quat="0.707107 0 0 0.707107" mass="0.000490673" diaginertia="1.27003e-08 9.79961e-09 4.84291e-09"/>
        
        <joint name="R_Hip_1" type="hinge" pos="0 0 0" axis="0 0 1"/>
        
        <geom type="mesh" contype="0" conaffinity="0" group="1" density="0" rgba="0.792157 0.819608 0.933333 1" mesh="R_Hip_1"/>
        <geom type="mesh" rgba="0.792157 0.819608 0.933333 1" mesh="R_Hip_1"/>
        
        <body name="R_Hip_2" pos="0 0 0.0076962" quat="0.529268 0.52927 0.468907 -0.468908">
          <inertial pos="-1.39156e-10 -1.14679e-09 0.0107683" quat="0.707107 0 0 0.707107" mass="0.00100456" diaginertia="4.56705e-08 3.43974e-08 1.53565e-08"/>
          
          <joint name="R_Hip_2" type="hinge" pos="0 0 0" axis="0 0 1"/>
          
          <geom type="mesh" contype="0" conaffinity="0" group="1" density="0" rgba="0.792157 0.819608 0.933333 1" mesh="R_Hip_2"/>
          <geom type="mesh" rgba="0.792157 0.819608 0.933333 1" mesh="R_Hip_2"/>
          
          <body name="R_Thigh" pos="0 0 0.013139" quat="0.397507 0.584796 0.584798 0.397509">
            <inertial pos="3.40459e-05 0.009 0" quat="0.707107 0.707107 0 0" mass="0.00259524" diaginertia="2.57116e-07 2.17945e-07 5.47709e-08"/>
            
            <joint name="R_Thigh" type="hinge" pos="0 0 0" axis="-1 0 0"/>
            
            <geom type="mesh" contype="0" conaffinity="0" group="1" density="0" rgba="1 1 0 1" mesh="R_Thigh"/>
            <geom type="mesh" rgba="1 1 0 1" mesh="R_Thigh"/>
            
            <body name="R_Foreleg" pos="0 0.018 0" quat="-1.92102e-06 3.13083e-06 -0.852343 0.522982">
              <inertial pos="0 0.0208617 -0.00148561" quat="0.684738 0.728789 0 0" mass="0.00244939" diaginertia="1.23016e-06 1.2006e-06 3.92157e-08"/>
              
              <joint name="R_Foreleg" type="hinge" pos="0 0 0" axis="-1 0 0" limited="true" range="-5 100" damping="0"/>
              
              <geom type="mesh" contype="0" conaffinity="0" group="1" density="0" rgba="0 1 1 1" mesh="R_Foreleg"/>
              <geom type="mesh" rgba="0 1 1 1" mesh="R_Foreleg"/>

              <body name="R_Shin" pos="0 0.064516 0" quat="0.868737 -0.495274 0 0">
                <inertial pos="4.16582e-05 0.0220307 -0.00550832" quat="0.819399 0.572189 -0.0177322 0.029512" mass="0.00129205" diaginertia="4.33834e-07 4.29412e-07 9.31982e-09"/>
                
                <joint name="R_Shin" type="hinge" pos="0 0 0" axis="-1 0 0"/>
                
                <geom type="mesh" contype="0" conaffinity="0" group="1" density="0" rgba="1 0 0 1" mesh="R_Shin"/>
                <geom type="mesh" rgba="1 0 0 1" mesh="R_Shin"/>

                <body name="R_Foot" pos="0 0.050358 -0.015576" quat="0.732642 0.680614 0 0">
                  <inertial pos="-1.65908e-10 0.000576078 -0.00529707" quat="0.503011 0.86428 0 0" mass="0.000518724" diaginertia="2.17999e-08 2.03996e-08 3.0822e-09"/>
                  
                  <joint name="R_Foot" type="hinge" pos="0 0 0" axis="-1 0 0"/>
                  
                  <geom type="mesh" contype="0" conaffinity="0" group="1" density="0" rgba="0.792157 0.819608 0.933333 1" mesh="R_Foot"/>
                  <geom type="mesh" rgba="0.792157 0.819608 0.933333 1" mesh="R_Foot_collision"/>
                
                </body>
                
                <body name="R_Servo" pos="-0.002 0.012585 0" quat="0.589405 0.390641 -0.39064 0.589407">
                  <inertial pos="0.000823287 -0.000486228 5.18374e-10" quat="-0.192327 0.680449 0.192327 0.680449" mass="0.000108566" diaginertia="9.03102e-10 7.73356e-10 4.25422e-10"/>
                  
                  <joint name="R_Servo" type="hinge" pos="0 0 0" axis="0 -1 0"/>
                  
                  <geom type="mesh" contype="0" conaffinity="0" group="1" density="0" rgba="0.792157 0.819608 0.933333 1" mesh="R_Servo"/>
                  <geom type="mesh" rgba="0.792157 0.819608 0.933333 1" mesh="R_Servo_collision"/>
                
                  <body name="R_Servo_Link" pos="0.0075599 0 0" quat="0.496083 -0.503885 0.503887 -0.496085">
                    <inertial pos="0 0.019315 0" quat="0.707107 0.707107 0 0" mass="5.90677e-05" diaginertia="7.67849e-09 7.67828e-09 1.55957e-11"/>
                    
                    <joint name="R_Servo_Link" type="hinge" pos="0 0 0" axis="-1 0 0"/>
                    
                    <geom type="mesh" contype="0" conaffinity="0" group="1" density="0" rgba="0.792157 0.819608 0.933333 1" mesh="R_Servo_Link"/>
                    <geom type="mesh" rgba="0.792157 0.819608 0.933333 1" mesh="R_Servo_Link"/>
                  </body>
                </body>
              </body>
            </body>
            
            <body name="R_Linkage" pos="-0.00575 0 0" quat="0.861134 -0.508378 0 0">
              <inertial pos="0 0.0331958 0" quat="0.707107 0.707107 0 0" mass="0.000113819" diaginertia="4.886e-08 4.88063e-08 7.27168e-11"/>
              
              <joint name="R_Linkage" type="hinge" pos="0 0 0" axis="-1 0 0"/>
              
              <geom type="mesh" contype="0" conaffinity="0" group="1" density="0" rgba="0.792157 0.819608 0.933333 1" mesh="R_Linkage"/>
              <geom type="mesh" rgba="0.792157 0.819608 0.933333 1" mesh="R_Linkage"/>
            </body>
          </body>
        </body>
      </body>
      
      <body name="L_Hip_1" pos="-0.021005 0 0" quat="0.707105 0.707108 0 0">
        <inertial pos="0 -4.8459e-06 0.00581975" quat="0.707107 0 0 0.707107" mass="0.000490673" diaginertia="1.27003e-08 9.79961e-09 4.84291e-09"/>
        
        <joint name="L_Hip_1" type="hinge" pos="0 0 0" axis="0 0 1"/>
        
        <geom type="mesh" contype="0" conaffinity="0" group="1" density="0" rgba="0.792157 0.819608 0.933333 1" mesh="L_Hip_1"/>
        <geom type="mesh" rgba="0.792157 0.819608 0.933333 1" mesh="L_Hip_1"/>
      
        <body name="L_Hip_2" pos="0 -0.013139 0.0076997" quat="-0.434184 -0.434178 -0.558113 0.558107">
          <inertial pos="4.80947e-06 -4.8459e-06 -0.00237034" quat="0.707107 0 0 0.707107" mass="0.00100456" diaginertia="4.56705e-08 3.43974e-08 1.53565e-08"/>
          
          <joint name="L_Hip_2" type="hinge" pos="0 0 0" axis="0 0 1"/>
          
          <geom type="mesh" contype="0" conaffinity="0" group="1" density="0" rgba="0.792157 0.819608 0.933333 1" mesh="L_Hip_2"/>
          <geom type="mesh" rgba="0.792157 0.819608 0.933333 1" mesh="L_Hip_2"/>
      
          <body name="L_Thigh" pos="0 0 0" quat="0.224207 -0.670619 0.670621 -0.224208">
            <inertial pos="3.88918e-05 -0.00795041 -0.0042224" quat="0.515038 0.857167 0 0" mass="0.00259524" diaginertia="2.57116e-07 2.17945e-07 5.47709e-08"/>
            
            <joint name="L_Thigh" type="hinge" pos="0 0 0" axis="-1 0 0"/>
            
            <geom type="mesh" contype="0" conaffinity="0" group="1" density="0" rgba="1 1 0 1" mesh="L_Thigh"/>
            <geom type="mesh" rgba="1 1 0 1" mesh="L_Thigh"/>
      
            <body name="L_Foreleg" pos="0 -0.015892 -0.0084481" quat="0.742702 -0.669622 0 0">
              <inertial pos="0 0.0208609 -0.00148863" quat="0.684711 0.728815 0 0" mass="0.00244939" diaginertia="1.23016e-06 1.2006e-06 3.92157e-08"/>
              
              <joint name="L_Foreleg" type="hinge" pos="0 0 0" axis="-1 0 0"/>
              
              <geom type="mesh" contype="0" conaffinity="0" group="1" density="0" rgba="0 1 1 1" mesh="L_Foreleg"/>
              <geom type="mesh" rgba="0 1 1 1" mesh="L_Foreleg"/>
      
              <body name="L_Shin" pos="0 0.064515 0" quat="0.843274 -0.537483 0 0">
                <inertial pos="-4.16582e-05 0.0220307 -0.00550832" quat="0.819399 0.572189 0.0177322 -0.029512" mass="0.00129205" diaginertia="4.33834e-07 4.29412e-07 9.31982e-09"/>
                
                <joint name="L_Shin" type="hinge" pos="0 0 0" axis="-1 0 0"/>
                
                <geom type="mesh" contype="0" conaffinity="0" group="1" density="0" rgba="1 0 0 1" mesh="L_Shin"/>
                <geom type="mesh" rgba="1 0 0 1" mesh="L_Shin"/>
      
                <body name="L_Foot" pos="0 0.050359 -0.015576" quat="0.54587 -0.449473 -0.449471 -0.545872">
                  <inertial pos="0.000576077 0 0.00529707" quat="0.355682 0.611139 0.611139 0.355682" mass="0.000518724" diaginertia="2.17999e-08 2.03996e-08 3.0822e-09"/>
                  
                  <joint name="L_Foot" type="hinge" pos="0 0 0" axis="0 -1 0"/>
                  
                  <geom type="mesh" contype="0" conaffinity="0" group="1" density="0" rgba="0.792157 0.819608 0.933333 1" mesh="L_Foot"/>
                  <geom type="mesh" rgba="0.792157 0.819608 0.933333 1" mesh="L_Foot_collision"/>
                </body>
      
                <body name="L_Servo" pos="0.002 0.012585 0" quat="-2.82204e-06 2.35128e-06 -0.640117 0.768278">
                  <inertial pos="0.000486228 -0.000823287 -5.20722e-10" quat="0.617145 0.345154 -0.617145 0.345154" mass="0.000108566" diaginertia="9.03102e-10 7.73356e-10 4.25422e-10"/>
                  
                  <joint name="L_Servo" type="hinge" pos="0 0 0" axis="-1 0 0"/>
                  
                  <geom type="mesh" contype="0" conaffinity="0" group="1" density="0" rgba="0.792157 0.819608 0.933333 1" mesh="L_Servo"/>
                  <geom type="mesh" rgba="0.792157 0.819608 0.933333 1" mesh="L_Servo_collision"/>
                  <body name="L_Servo_Link" pos="0 -0.0075599 0" quat="-2.25195e-06 2.90192e-06 0.790025 -0.613074">
                    <inertial pos="0 0.019315 0" quat="0.707107 0.707107 0 0" mass="5.90677e-05" diaginertia="7.67849e-09 7.67828e-09 1.55957e-11"/>
                    
                    <joint name="L_Servo_Link" type="hinge" pos="0 0 0" axis="-1 0 0"/>
                    
                    <geom type="mesh" contype="0" conaffinity="0" group="1" density="0" rgba="0.792157 0.819608 0.933333 1" mesh="L_Servo_Link"/>
                    <geom type="mesh" rgba="0.792157 0.819608 0.933333 1" mesh="L_Servo_Link"/>
                  </body>
                </body>
              </body>
            </body>
      
            <body name="L_Linkage" pos="-0.0057452 0 0" quat="0.730529 -0.682882 0 0">
              <inertial pos="0 0.0331958 2.39075e-12" quat="0.707107 0.707107 0 0" mass="0.000113819" diaginertia="4.886e-08 4.88063e-08 7.27168e-11"/>
              
              <joint name="L_Linkage" type="hinge" pos="0 0 0" axis="1 0 0"/>
              
              <geom type="mesh" contype="0" conaffinity="0" group="1" density="0" rgba="0.792157 0.819608 0.933333 1" mesh="L_Linkage"/>
              <geom type="mesh" rgba="0.792157 0.819608 0.933333 1" mesh="L_Linkage"/>
            </body>
          </body>
        </body>
      </body>
    </body>
  </worldbody>

  <equality>
    <connect body1="R_Linkage"   body2="R_Shin"   anchor="0 0.0669 0"/>
    <connect body1="L_Linkage"   body2="L_Shin"   anchor="0 0.0669 0"/>
    <connect body1="R_Servo_Link"   body2="R_Foot"   anchor="0 0.0386 0"/>
    <connect body1="L_Servo_Link"   body2="L_Foot"   anchor="0 0.0386 0"/>
  </equality>

  <actuator>
    <!-- User parameter is the maximum no-load motor RPM -->
    <!-- Right Leg Motors -->
    <motor name="R_Hip_1"     joint="R_Hip_1"     gear=".25"   ctrlrange="-.00001 .00001"/>
    <motor name="R_Hip_2"     joint="R_Hip_2"     gear=".25"   ctrlrange="-.00001 .00001"/>
    <motor name="R_Thigh"     joint="R_Thigh"     gear=".16"   ctrlrange="-.00001 .00001"/>
    <motor name="R_Foreleg"   joint="R_Foreleg"   gear=".16"   ctrlrange="-.00001 .00001"/>
    <motor name="R_Foot"      joint="R_Servo"     gear=".50"   ctrlrange="-.00001 .00001"/>

    <!-- Left Leg Motors -->
    <motor name="L_Hip_1"     joint="L_Hip_1"     gear=".25"   ctrlrange="-.00001 .00001"/>
    <motor name="L_Hip_2"     joint="L_Hip_2"     gear=".25"   ctrlrange="-.00001 .00001"/>
    <motor name="L_Thigh"     joint="L_Thigh"     gear=".16"   ctrlrange="-.00001 .00001"/>
    <motor name="L_Foreleg"   joint="L_Foreleg"   gear=".16"   ctrlrange="-.00001 .00001"/>
    <motor name="L_Foot"      joint="L_Servo"     gear=".50"   ctrlrange="-.00001 .00001"/>

  </actuator>
</mujoco>
