<?xml version="1.0" encoding="utf-8"?>
<!-- This URDF was automatically created by SolidWorks to URDF Exporter! Originally created by Stephen Brawner (brawner@gmail.com) 
     Commit Version: 1.6.0-4-g7f85cfe  Build Version: 1.6.7995.38578
     For more information, please see http://wiki.ros.org/sw_urdf_exporter -->
<robot
  name="Cassie_mock_up.SLDASM">
  <link
    name="base_link">
    <inertial>
      <origin
        xyz="3.865E-08 0.13049 -0.0010906"
        rpy="0 0 0" />
      <mass
        value="0.029923" />
      <inertia
        ixx="4.6443E-06"
        ixy="1.4595E-11"
        ixz="7.0006E-12"
        iyy="5.9625E-06"
        iyz="7.6579E-08"
        izz="4.7898E-06" />
    </inertial>
    <visual>
      <origin
        xyz="0 0 0"
        rpy="0 0 0" />
      <geometry>
        <mesh
          filename="package://Cassie_mock_up.SLDASM/meshes/base_link.STL" />
      </geometry>
      <material
        name="">
        <color
          rgba="0.50196 0.50196 0.50196 1" />
      </material>
    </visual>
    <collision>
      <origin
        xyz="0 0 0"
        rpy="0 0 0" />
      <geometry>
        <mesh
          filename="package://Cassie_mock_up.SLDASM/meshes/base_link.STL" />
      </geometry>
    </collision>
  </link>
  <link
    name="L Hip 1">
    <inertial>
      <origin
        xyz="0.021005 0.12932 0.0062198"
        rpy="0 0 0" />
      <mass
        value="0.00049067" />
      <inertia
        ixx="9.7996E-09"
        ixy="7.0191E-25"
        ixz="7.3896E-25"
        iyy="1.27E-08"
        iyz="-1.0393E-24"
        izz="4.8429E-09" />
    </inertial>
    <visual>
      <origin
        xyz="0 0 0"
        rpy="0 0 0" />
      <geometry>
        <mesh
          filename="package://Cassie_mock_up.SLDASM/meshes/L Hip 1.STL" />
      </geometry>
      <material
        name="">
        <color
          rgba="0.79216 0.81961 0.93333 1" />
      </material>
    </visual>
    <collision>
      <origin
        xyz="0 0 0"
        rpy="0 0 0" />
      <geometry>
        <mesh
          filename="package://Cassie_mock_up.SLDASM/meshes/L Hip 1.STL" />
      </geometry>
    </collision>
  </link>
  <joint
    name="Joint 0L"
    type="revolute">
    <origin
      xyz="-0.04201 0 0"
      rpy="1.5708 0 0" />
    <parent
      link="base_link" />
    <child
      link="L Hip 1" />
    <axis
      xyz="0 0 0" />
    <limit
      lower="0"
      upper="0"
      effort="0"
      velocity="0" />
  </joint>
  <link
    name="L Hip 2">
    <inertial>
      <origin
        xyz="-1.7347E-18 0 -0.0098704"
        rpy="0 0 0" />
      <mass
        value="0.0010046" />
      <inertia
        ixx="3.4397E-08"
        ixy="4.3427E-23"
        ixz="2.3169E-24"
        iyy="4.567E-08"
        iyz="-1.917E-23"
        izz="1.5356E-08" />
    </inertial>
    <visual>
      <origin
        xyz="0 0 0"
        rpy="0 0 0" />
      <geometry>
        <mesh
          filename="package://Cassie_mock_up.SLDASM/meshes/L Hip 2.STL" />
      </geometry>
      <material
        name="">
        <color
          rgba="0.79216 0.81961 0.93333 1" />
      </material>
    </visual>
    <collision>
      <origin
        xyz="0 0 0"
        rpy="0 0 0" />
      <geometry>
        <mesh
          filename="package://Cassie_mock_up.SLDASM/meshes/L Hip 2.STL" />
      </geometry>
    </collision>
  </link>
  <joint
    name="Joint 1 L"
    type="revolute">
    <origin
      xyz="0.021005 0.10918 0.0080962"
      rpy="1.5708 -1.4127 0" />
    <parent
      link="L Hip 1" />
    <child
      link="L Hip 2" />
    <axis
      xyz="0 0 1" />
    <limit
      lower="0"
      upper="0"
      effort="0"
      velocity="0" />
  </joint>
  <link
    name="L thigh">
    <inertial>
      <origin
        xyz="3.4046E-05 -0.0079465 -0.0042252"
        rpy="0 0 0" />
      <mass
        value="0.0025952" />
      <inertia
        ixx="2.5712E-07"
        ixy="-1.3235E-23"
        ixz="-6.6174E-24"
        iyy="9.0735E-08"
        iyz="-6.7639E-08"
        izz="1.8198E-07" />
    </inertial>
    <visual>
      <origin
        xyz="0 0 0"
        rpy="0 0 0" />
      <geometry>
        <mesh
          filename="package://Cassie_mock_up.SLDASM/meshes/L thigh.STL" />
      </geometry>
      <material
        name="">
        <color
          rgba="1 1 0 1" />
      </material>
    </visual>
    <collision>
      <origin
        xyz="0 0 0"
        rpy="0 0 0" />
      <geometry>
        <mesh
          filename="package://Cassie_mock_up.SLDASM/meshes/L thigh.STL" />
      </geometry>
    </collision>
  </link>
  <joint
    name="Join 2 L"
    type="revolute">
    <origin
      xyz="0 0 -0.0075"
      rpy="-2.7684 0 1.5708" />
    <parent
      link="L Hip 2" />
    <child
      link="L thigh" />
    <axis
      xyz="1 0 0" />
    <limit
      lower="0"
      upper="0"
      effort="0"
      velocity="0" />
  </joint>
  <link
    name="L foreleg">
    <inertial>
      <origin
        xyz="-3.4694E-18 -0.01815 0.010393"
        rpy="0 0 0" />
      <mass
        value="0.0024494" />
      <inertia
        ixx="1.2302E-06"
        ixy="-1.2739E-22"
        ixz="7.9409E-23"
        iyy="4.6842E-07"
        iyz="5.6059E-07"
        izz="7.714E-07" />
    </inertial>
    <visual>
      <origin
        xyz="0 0 0"
        rpy="0 0 0" />
      <geometry>
        <mesh
          filename="package://Cassie_mock_up.SLDASM/meshes/L foreleg.STL" />
      </geometry>
      <material
        name="">
        <color
          rgba="0 1 1 1" />
      </material>
    </visual>
    <collision>
      <origin
        xyz="0 0 0"
        rpy="0 0 0" />
      <geometry>
        <mesh
          filename="package://Cassie_mock_up.SLDASM/meshes/L foreleg.STL" />
      </geometry>
    </collision>
  </link>
  <joint
    name="Joint 3 L"
    type="revolute">
    <origin
      xyz="0 -0.015893 -0.0084505"
      rpy="1.7931 0 -3.1416" />
    <parent
      link="L thigh" />
    <child
      link="L foreleg" />
    <axis
      xyz="1 0 0" />
    <limit
      lower="0"
      upper="0"
      effort="0"
      velocity="0" />
  </joint>
  <link
    name="L Shin">
    <inertial>
      <origin
        xyz="-0.021572 0.029362 4.1658E-05"
        rpy="0 0 0" />
      <mass
        value="0.001292" />
      <inertia
        ixx="2.2474E-07"
        ixy="2.0998E-07"
        ixz="1.1797E-09"
        iyy="2.1403E-07"
        iyz="-1.644E-09"
        izz="4.338E-07" />
    </inertial>
    <visual>
      <origin
        xyz="0 0 0"
        rpy="0 0 0" />
      <geometry>
        <mesh
          filename="package://Cassie_mock_up.SLDASM/meshes/L Shin.STL" />
      </geometry>
      <material
        name="">
        <color
          rgba="1 0 0 1" />
      </material>
    </visual>
    <collision>
      <origin
        xyz="0 0 0"
        rpy="0 0 0" />
      <geometry>
        <mesh
          filename="package://Cassie_mock_up.SLDASM/meshes/L Shin.STL" />
      </geometry>
    </collision>
  </link>
  <joint
    name="Joint 4 L"
    type="revolute">
    <origin
      xyz="0 -0.081401 -0.016224"
      rpy="1.5708 1.136 1.5708" />
    <parent
      link="L foreleg" />
    <child
      link="L Shin" />
    <axis
      xyz="0 0 0" />
    <limit
      lower="0"
      upper="0"
      effort="0"
      velocity="0" />
  </joint>
  <link
    name="L feet">
    <inertial>
      <origin
        xyz="0.0011481 0.0026645 0"
        rpy="0 0 0" />
      <mass
        value="0.00051872" />
      <inertia
        ixx="3.0999E-09"
        ixy="5.5367E-10"
        ixz="3.6189E-25"
        iyy="2.0382E-08"
        iyz="1.3959E-24"
        izz="2.18E-08" />
    </inertial>
    <visual>
      <origin
        xyz="0 0 0"
        rpy="0 0 0" />
      <geometry>
        <mesh
          filename="package://Cassie_mock_up.SLDASM/meshes/L feet.STL" />
      </geometry>
      <material
        name="">
        <color
          rgba="0.79216 0.81961 0.93333 1" />
      </material>
    </visual>
    <collision>
      <origin
        xyz="0 0 0"
        rpy="0 0 0" />
      <geometry>
        <mesh
          filename="package://Cassie_mock_up.SLDASM/meshes/L feet.STL" />
      </geometry>
    </collision>
  </link>
  <joint
    name="End Effector L"
    type="revolute">
    <origin
      xyz="-0.0021664 7.7104E-05 0"
      rpy="0 0 -0.28389" />
    <parent
      link="L Shin" />
    <child
      link="L feet" />
    <axis
      xyz="0 0 0" />
    <limit
      lower="0"
      upper="0"
      effort="0"
      velocity="0" />
  </joint>
  <link
    name="R Hip 1">
    <inertial>
      <origin
        xyz="0 0 0"
        rpy="0 0 0" />
      <mass
        value="0" />
      <inertia
        ixx="0"
        ixy="0"
        ixz="0"
        iyy="0"
        iyz="0"
        izz="0" />
    </inertial>
    <visual>
      <origin
        xyz="0 0 0"
        rpy="0 0 0" />
      <geometry>
        <mesh
          filename="package://Cassie_mock_up.SLDASM/meshes/R Hip 1.STL" />
      </geometry>
      <material
        name="">
        <color
          rgba="1 1 1 1" />
      </material>
    </visual>
    <collision>
      <origin
        xyz="0 0 0"
        rpy="0 0 0" />
      <geometry>
        <mesh
          filename="package://Cassie_mock_up.SLDASM/meshes/R Hip 1.STL" />
      </geometry>
    </collision>
  </link>
  <joint
    name="Joint 0 R"
    type="revolute">
    <origin
      xyz="0.04201 0 0"
      rpy="1.5708 0 3.1416" />
    <parent
      link="base_link" />
    <child
      link="R Hip 1" />
    <axis
      xyz="0 0 0" />
    <limit
      lower="0"
      upper="0"
      effort="0"
      velocity="0" />
  </joint>
  <link
    name="R Hip 2">
    <inertial>
      <origin
        xyz="-1.7347E-18 0 0.0098704"
        rpy="0 0 0" />
      <mass
        value="0.0010046" />
      <inertia
        ixx="3.4397E-08"
        ixy="3.5982E-23"
        ixz="-2.4454E-24"
        iyy="4.567E-08"
        iyz="2.1931E-23"
        izz="1.5356E-08" />
    </inertial>
    <visual>
      <origin
        xyz="0 0 0"
        rpy="0 0 0" />
      <geometry>
        <mesh
          filename="package://Cassie_mock_up.SLDASM/meshes/R Hip 2.STL" />
      </geometry>
      <material
        name="">
        <color
          rgba="0.79216 0.81961 0.93333 1" />
      </material>
    </visual>
    <collision>
      <origin
        xyz="0 0 0"
        rpy="0 0 0" />
      <geometry>
        <mesh
          filename="package://Cassie_mock_up.SLDASM/meshes/R Hip 2.STL" />
      </geometry>
    </collision>
  </link>
  <joint
    name="Joint 1 R"
    type="continuous">
    <origin
      xyz="0.021005 0.10918 -0.0080962"
      rpy="-1.5708 1.4127 0" />
    <parent
      link="R Hip 1" />
    <child
      link="R Hip 2" />
    <axis
      xyz="0 0 1" />
  </joint>
  <link
    name="R thigh">
    <inertial>
      <origin
        xyz="3.4046E-05 -0.0079465 0.0042252"
        rpy="0 0 0" />
      <mass
        value="0.0025952" />
      <inertia
        ixx="2.5712E-07"
        ixy="1.4889E-23"
        ixz="2.4815E-24"
        iyy="9.0735E-08"
        iyz="6.7639E-08"
        izz="1.8198E-07" />
    </inertial>
    <visual>
      <origin
        xyz="0 0 0"
        rpy="0 0 0" />
      <geometry>
        <mesh
          filename="package://Cassie_mock_up.SLDASM/meshes/R thigh.STL" />
      </geometry>
      <material
        name="">
        <color
          rgba="0.79216 0.81961 0.93333 1" />
      </material>
    </visual>
    <collision>
      <origin
        xyz="0 0 0"
        rpy="0 0 0" />
      <geometry>
        <mesh
          filename="package://Cassie_mock_up.SLDASM/meshes/R thigh.STL" />
      </geometry>
    </collision>
  </link>
  <joint
    name="Joint 2 R"
    type="revolute">
    <origin
      xyz="0 0 0.0075"
      rpy="2.7684 0 1.5708" />
    <parent
      link="R Hip 2" />
    <child
      link="R thigh" />
    <axis
      xyz="1 0 0" />
    <limit
      lower="0"
      upper="0"
      effort="0"
      velocity="0" />
  </joint>
  <link
    name="R foreleg">
    <inertial>
      <origin
        xyz="-3.4694E-18 -0.01815 -0.010393"
        rpy="0 0 0" />
      <mass
        value="0.0024494" />
      <inertia
        ixx="1.2302E-06"
        ixy="-9.4299E-23"
        ixz="2.647E-23"
        iyy="4.6842E-07"
        iyz="-5.6059E-07"
        izz="7.714E-07" />
    </inertial>
    <visual>
      <origin
        xyz="0 0 0"
        rpy="0 0 0" />
      <geometry>
        <mesh
          filename="package://Cassie_mock_up.SLDASM/meshes/R foreleg.STL" />
      </geometry>
      <material
        name="">
        <color
          rgba="0 1 1 1" />
      </material>
    </visual>
    <collision>
      <origin
        xyz="0 0 0"
        rpy="0 0 0" />
      <geometry>
        <mesh
          filename="package://Cassie_mock_up.SLDASM/meshes/R foreleg.STL" />
      </geometry>
    </collision>
  </link>
  <joint
    name="Joint 3 R"
    type="revolute">
    <origin
      xyz="0 -0.015893 0.0084505"
      rpy="-1.7931 0 3.1416" />
    <parent
      link="R thigh" />
    <child
      link="R foreleg" />
    <axis
      xyz="1 0 0" />
    <limit
      lower="0"
      upper="0"
      effort="0"
      velocity="0" />
  </joint>
  <link
    name="R shin">
    <inertial>
      <origin
        xyz="-0.021572 0.029362 -4.1658E-05"
        rpy="0 0 0" />
      <mass
        value="0.001292" />
      <inertia
        ixx="2.2474E-07"
        ixy="2.0998E-07"
        ixz="-1.1797E-09"
        iyy="2.1403E-07"
        iyz="1.644E-09"
        izz="4.338E-07" />
    </inertial>
    <visual>
      <origin
        xyz="0 0 0"
        rpy="0 0 0" />
      <geometry>
        <mesh
          filename="package://Cassie_mock_up.SLDASM/meshes/R shin.STL" />
      </geometry>
      <material
        name="">
        <color
          rgba="1 0 0 1" />
      </material>
    </visual>
    <collision>
      <origin
        xyz="0 0 0"
        rpy="0 0 0" />
      <geometry>
        <mesh
          filename="package://Cassie_mock_up.SLDASM/meshes/R shin.STL" />
      </geometry>
    </collision>
  </link>
  <joint
    name="Joint 4 R"
    type="revolute">
    <origin
      xyz="0 -0.081401 0.016224"
      rpy="-1.5708 -1.136 1.5708" />
    <parent
      link="R foreleg" />
    <child
      link="R shin" />
    <axis
      xyz="0 0 0" />
    <limit
      lower="0"
      upper="0"
      effort="0"
      velocity="0" />
  </joint>
  <link
    name="R feet">
    <inertial>
      <origin
        xyz="0.0011481 0.0026645 0"
        rpy="0 0 0" />
      <mass
        value="0.00051872" />
      <inertia
        ixx="3.0999E-09"
        ixy="5.5367E-10"
        ixz="8.9439E-24"
        iyy="2.0382E-08"
        iyz="8.918E-25"
        izz="2.18E-08" />
    </inertial>
    <visual>
      <origin
        xyz="0 0 0"
        rpy="0 0 0" />
      <geometry>
        <mesh
          filename="package://Cassie_mock_up.SLDASM/meshes/R feet.STL" />
      </geometry>
      <material
        name="">
        <color
          rgba="0.79216 0.81961 0.93333 1" />
      </material>
    </visual>
    <collision>
      <origin
        xyz="0 0 0"
        rpy="0 0 0" />
      <geometry>
        <mesh
          filename="package://Cassie_mock_up.SLDASM/meshes/R feet.STL" />
      </geometry>
    </collision>
  </link>
  <joint
    name="End Effector R"
    type="revolute">
    <origin
      xyz="-0.0021664 7.7104E-05 0"
      rpy="0 0 -0.28389" />
    <parent
      link="R shin" />
    <child
      link="R feet" />
    <axis
      xyz="0 0 0" />
    <limit
      lower="0"
      upper="0"
      effort="0"
      velocity="0" />
  </joint>
</robot>